tests/100instruments-60kOrders.in
30
0-29 o
.
9 S 1 VNCS 19026 316
13 B 2 CFWA 16567 863
7 S 3 HFYS 685 430
3 B 4 HYVS 14707 180
23 S 5 YJMH 10850 377
25 B 6 THTI 12218 314
11 S 7 OBEV 9804 366
3 B 8 JWUI 7746 929
14 S 9 VIJX 3390 135
21 S 10 RBSG 7157 137
15 S 11 HGRP 12042 709
26 S 12 OVDB 13795 665
18 S 13 ZPFY 18579 729
22 S 14 XQFV 11427 370
11 S 15 RUOF 13529 982
22 S 16 RECZ 5810 546
9 B 17 CFSQ 10528 172
23 S 18 NBCZ 8240 80
7 S 19 JSBG 91 672
25 B 20 BFVJ 13905 189
2 S 21 LRVQ 3789 741
19 S 22 VJHP 9486 34
20 S 23 TTLX 9434 774
24 S 24 VSDF 7351 195
0 B 25 LFLP 8442 870
7 B 26 SKFK 8324 949
24 S 27 WOTX 3056 176
17 S 28 IACA 6200 175
10 S 29 DATU 10535 487
23 B 30 INAX 729 370
20 S 31 RECZ 14977 973
24 S 32 DDGV 3132 274
24 B 33 CDKI 4711 622
14 S 34 YVEY 6571 601
25 B 35 TASJ 16526 1
9 B 36 DMRH 14695 533
6 S 37 HKFO 13074 592
8 B 38 RABD 5058 584
13 S 39 IULN 16515 566
6 S 40 JNCW 15575 351
22 S 41 FAMN 17212 840
22 S 42 AAPR 19721 724
15 S 43 BXNX 17994 767
11 B 44 DUBW 11034 481
16 S 45 DZAG 3729 779
3 B 46 DRSD 9821 56
12 B 47 LFPP 1019 902
23 S 48 QZIM 5266 412
22 B 49 BIPE 14416 189
19 B 50 LYUU 7726 32
2 S 51 NLVH 6314 212
8 B 52 DMRH 9241 345
26 B 53 PZTT 10940 902
16 B 54 OMMP 4403 748
26 B 55 LCCQ 7238 89
9 B 56 KDJY 9663 984
16 S 57 CLVT 12463 845
22 B 58 LFLP 17224 164
13 B 59 NJRN 5893 193
16 B 60 UHWS 11562 973
12 S 61 DBAJ 6973 742
18 B 62 QVZF 6120 377
4 S 63 HNZV 4142 836
27 B 64 CDKI 788 186
18 B 65 GEVQ 9670 846
26 B 66 UBUU 11414 211
13 B 67 LSVG 1372 325
27 B 68 SBXK 2609 641
22 B 69 PZTT 16187 162
5 S 70 WISB 8681 803
12 B 71 POYY 2119 891
12 B 72 BCZS 19482 515
10 B 73 BZEJ 2984 23
4 B 74 PSZR 17625 748
23 B 75 VPCQ 15167 36
20 B 76 QVMV 17620 942
26 S 77 USII 8064 328
18 S 78 QTZY 5157 182
14 B 79 KSFL 5380 321
28 S 80 GEVQ 13406 392
11 B 81 THTI 2759 802
29 B 82 RUOF 18440 158
25 B 83 SFPA 18220 319
22 S 84 RFEB 4008 431
10 S 85 MVOJ 12348 149
6 B 86 JSBG 15455 4
1 B 87 ZJSC 1817 604
18 B 88 LFPP 12895 846
11 S 89 ZVIO 7582 71
10 S 90 CFSQ 5828 121
15 B 91 MUCA 6845 905
18 B 92 TKFX 16312 440
14 B 93 ZJSC 19580 224
5 S 94 OIDC 4492 581
3 B 95 ZHSN 16279 653
1 S 96 MRKC 6539 30
18 S 97 OWWJ 18493 866
25 B 98 FDQZ 6006 386
2 S 99 QVZF 18033 499
27 S 100 VSDF 12611 833
7 S 101 MRKC 712 303
16 B 102 BXNX 15954 905
15 B 103 FAMN 19546 49
27 B 104 KNIG 13971 922
3 B 105 IACA 14801 732
11 S 106 JWUI 16411 12
12 S 107 LMOP 1689 867
5 S 108 BOXK 19083 483
18 B 109 QGFQ 14141 864
15 S 110 NLVH 13452 768
10 B 111 KWID 18991 524
29 S 112 RUOF 18322 513
22 S 113 CRSH 8363 822
12 S 114 FZJE 8287 745
20 S 115 LFPP 19106 3
27 S 116 LTHY 11003 537
3 B 117 YJMH 1457 118
24 S 118 IPIA 8507 11
5 B 119 JTHI 15392 649
24 B 120 XBVQ 214 447
25 B 121 IBIF 922 456
17 B 122 TFYF 15526 98
26 S 123 IEOJ 12011 346
0 S 124 GXUG 17295 103
15 S 125 ENTQ 10885 957
14 S 126 WSPN 5527 383
4 S 127 OUYR 2766 375
26 S 128 DGRB 15716 478
13 B 129 CWMH 18825 679
9 B 130 HLNB 6323 999
25 B 131 IPPZ 15000 20
7 B 132 IQAX 2249 572
28 S 133 HNZV 11328 1
2 S 134 NUIN 14524 473
10 B 135 OPIS 2470 66
20 S 136 LSVG 3945 955
26 S 137 ADHP 3233 865
22 B 138 TTLX 228 608
5 B 139 FJPN 1133 501
27 B 140 DAWR 10519 167
11 B 141 MVOJ 6034 523
14 S 142 UBUU 7967 797
1 B 143 QVMV 19820 421
7 B 144 BOXK 17994 826
5 S 145 JTUU 16122 894
15 B 146 EIRS 9815 963
26 S 147 RZGX 12094 883
11 B 148 YRPP 11419 485
5 B 149 BWFB 17564 230
2 B 150 CFSQ 5090 921
1 B 151 KWCQ 1471 359
14 B 152 BZMJ 6038 776
26 B 153 ZWNY 18580 176
12 S 154 RUOF 12777 925
23 B 155 WDCK 11548 888
14 B 156 USII 15426 796
23 S 157 LOAJ 4151 186
27 B 158 BFVJ 627 235
17 B 159 WSPN 3987 493
2 S 160 JTUU 12913 468
24 B 161 QGGV 4786 26
17 B 162 XDOO 4488 534
27 S 163 WMYL 13336 321
5 B 164 DZAG 16968 278
10 S 165 QGFQ 16254 976
16 S 166 CSNF 4408 578
27 S 167 REAH 13726 939
26 B 168 SUDV 14100 373
21 S 169 VPCQ 11545 196
1 S 170 NPFL 18309 393
3 B 171 XZST 2432 208
0 S 172 ZBCH 7073 281
6 S 173 YSUJ 7458 775
17 B 174 QYDI 9492 530
18 S 175 IPIA 16618 149
2 S 176 ZEAU 10834 739
5 S 177 JZHQ 1045 435
28 S 178 IACA 2331 106
4 S 179 LFLP 19277 508
20 B 180 VNHL 3965 964
12 B 181 AWOB 19004 112
25 B 182 UHWS 17551 799
27 B 183 NOAT 6719 62
7 S 184 LFLP 12096 496
13 S 185 WOTX 18133 362
21 B 186 PWSN 12075 722
20 S 187 YRPP 5184 971
25 B 188 RVKD 14217 623
21 B 189 LSVG 1271 174
14 S 190 GEVQ 9306 370
14 B 191 CFSQ 2548 654
9 S 192 DGRB 4149 406
7 S 193 ZVIO 2917 871
12 S 194 SWVO 16038 338
21 S 195 OBEV 5965 618
21 B 196 SAJU 13825 872
28 B 197 LDUM 1630 122
17 B 198 PZTT 8297 672
29 B 199 WOTX 2323 370
19 S 200 MUCA 13350 250
13 S 201 JNCW 9100 739
7 S 202 SSCV 16905 198
7 B 203 IACA 14467 806
15 B 204 OWWJ 16766 383
29 B 205 NHCH 9962 965
28 B 206 ZJSC 2196 131
23 S 207 XUNZ 9843 548
27 B 208 NDJW 7302 468
14 S 209 ASJA 1466 885
1 S 210 HXXP 10462 152
0 B 211 HXXP 16255 330
7 S 212 SAJU 618 444
3 B 213 HKFO 13551 264
8 S 214 LOAJ 5339 435
4 B 215 QRWL 11195 51
12 S 216 ASJA 4015 945
2 B 217 JWUI 13487 84
0 B 218 ZEAU 8522 806
28 B 219 CMDC 8751 932
27 S 220 CWMH 5058 644
1 B 221 WOTX 6059 733
21 B 222 AAEM 9468 91
21 S 223 KQAO 15486 141
13 B 224 QYDI 15582 160
23 B 225 OPIS 12890 168
11 B 226 EAAF 9455 584
22 S 227 INAX 181 313
13 B 228 VJHP 6143 664
10 S 229 DZAG 17943 512
29 B 230 QVZF 6215 610
12 S 231 FJPN 19757 108
7 S 232 DUSF 19347 335
25 S 233 TMFX 19614 605
6 B 234 HVQT 7242 238
2 S 235 IBPC 13410 66
11 S 236 DRSD 16946 507
10 S 237 CFSQ 13569 106
0 B 238 DBAJ 16249 173
19 B 239 KSEP 19896 715
23 S 240 YSUJ 9171 843
3 S 241 CMDC 13585 763
13 S 242 KKCN 16219 634
1 S 243 XBVQ 6747 789
1 B 244 CDKI 18914 238
20 S 245 NYDR 9118 596
29 S 246 YOJC 13977 544
8 B 247 UEAZ 3694 262
8 B 248 HYLH 18653 262
27 S 249 MVOJ 11131 367
4 B 250 BXNX 795 114
5 B 251 QCWA 1205 70
9 B 252 FROY 4178 380
15 S 253 OZAF 7388 517
0 S 254 ZPFY 13113 357
0 S 255 INAX 2984 428
11 S 256 RLGA 7040 322
13 B 257 IPIA 8157 885
9 S 258 JTHI 17330 958
21 B 259 QCWA 14703 918
15 S 260 FCZN 11919 183
28 B 261 LFPP 8162 406
7 B 262 REAH 1416 986
26 S 263 FCYA 18101 995
20 B 264 LQPZ 1138 581
18 B 265 VIJX 19723 691
22 S 266 XEEH 7719 41
9 B 267 YVEY 5010 125
29 S 268 DNLH 4203 126
17 S 269 HQLW 8169 965
20 B 270 UMPG 19461 893
5 B 271 ZBCH 2940 91
9 B 272 FDQZ 19965 783
26 S 273 VCXR 3406 787
15 B 274 WISB 15682 876
25 B 275 IPPZ 17836 530
5 B 276 VKMZ 15171 368
16 S 277 KKCN 14005 322
0 B 278 QOEH 16659 272
29 B 279 INAX 1257 668
0 B 280 EDAZ 6370 46
24 B 281 IBPC 4765 853
12 B 282 HHRF 9156 824
29 S 283 LOAJ 10997 321
19 S 284 LQPZ 1832 34
1 B 285 RECZ 11593 837
2 B 286 KSFL 6086 634
8 S 287 ZBCH 2732 102
3 S 288 PWSN 3994 979
9 S 289 RCHF 19943 797
21 B 290 TDAT 7018 152
25 S 291 RVKD 19878 319
14 B 292 REAH 7222 383
4 S 293 TKFX 10833 115
0 B 294 XUNZ 6908 445
20 S 295 CFWA 9547 448
24 S 296 RZGX 19761 824
20 S 297 XEEH 9746 619
5 B 298 FZJE 18508 871
24 S 299 TFYF 6558 758
0 S 300 MVOJ 11375 437
11 B 301 IPIA 18318 491
27 B 302 LYUU 3048 625
22 S 303 NHCH 7322 97
22 B 304 NXBM 19407 448
4 B 305 WISB 4745 977
29 S 306 JFXE 14869 494
19 B 307 OKRR 19945 873
10 B 308 IBIF 4069 460
0 B 309 DDGV 5174 948
7 B 310 EAAF 3363 321
15 S 311 SOSM 3422 276
1 S 312 XAJS 5016 726
23 B 313 MQMS 840 645
24 S 314 BWFB 1538 231
23 S 315 FXFJ 5513 120
25 B 316 UMPG 1712 327
19 B 317 WMYL 11312 725
20 S 318 ZUBK 4004 454
18 S 319 OZAF 11486 126
10 B 320 YFBY 10691 998
26 B 321 ADHP 13755 754
3 S 322 QGFQ 2344 705
2 S 323 KQTY 13911 281
16 B 324 KKCN 8720 769
3 S 325 DNLH 5655 561
9 B 326 TASJ 13105 346
17 S 327 YHZV 5195 500
10 B 328 XUNZ 6513 545
26 B 329 DPEJ 14651 354
9 B 330 CRSH 16585 256
11 B 331 YFBY 8697 654
8 S 332 RVKD 9627 308
26 S 333 WABF 3281 422
0 S 334 NYPM 9515 156
8 S 335 BFVJ 2438 846
1 B 336 HHRF 9377 783
5 S 337 OPIS 13016 342
12 B 338 AAPR 1916 628
19 B 339 NZFS 16247 153
29 B 340 JWUI 5993 426
26 S 341 LDUM 7623 749
9 B 342 TUWP 15631 601
4 B 343 XUNZ 4168 688
26 S 344 TMFX 12651 490
22 S 345 FCZN 2589 224
27 B 346 RIYW 2563 442
23 B 347 EDAZ 18013 653
10 S 348 CLVT 5328 774
0 B 349 MAJL 8834 837
21 B 350 TDTV 1550 546
24 S 351 KBJL 9545 793
3 S 352 WSPN 18593 167
12 S 353 VNHL 14753 406
