tests/300instruments-60kOrders.in
30
0-29 o
.
1 S 1 IQPD 15253 57
1 S 2 VCXR 5480 500
18 B 3 NBCZ 12905 878
23 B 4 KDJY 16992 952
7 B 5 CMDC 19729 338
10 S 6 LMOP 11735 652
5 S 7 QIDO 4414 20
2 S 8 LQOQ 4921 194
23 B 9 NYPM 8971 599
1 S 10 NDXH 10817 635
10 B 11 HVQT 18029 818
23 B 12 OSUM 3923 48
7 S 13 XZST 13158 22
14 B 14 SKYK 18011 702
17 B 15 HQUS 17362 743
11 S 16 FROY 4134 117
21 B 17 DPXG 5000 211
29 B 18 BFVJ 16103 856
10 S 19 CYFZ 13223 571
25 S 20 DDGV 6659 142
5 S 21 GXUG 17936 332
20 S 22 BWFB 405 26
23 B 23 BZJB 17816 799
6 B 24 WHAG 1812 219
16 S 25 QRWL 8383 552
21 B 26 XDOO 5148 906
11 B 27 RVKD 4650 104
27 B 28 BZEJ 19087 693
12 S 29 SUDL 11886 822
13 B 30 ENTQ 15826 323
0 B 31 PWMS 2391 54
26 S 32 YUED 8389 770
2 S 33 KWID 984 351
3 S 34 YQBN 15420 465
4 S 35 SHWF 7102 777
17 S 36 BZEJ 6717 680
16 B 37 TASJ 3370 431
20 B 38 UMPG 16033 45
18 B 39 XKQE 19912 392
5 B 40 OWWJ 19401 919
8 B 41 BFVJ 17235 389
16 B 42 OPIS 2861 223
4 B 43 JWUI 14256 125
3 S 44 PMCI 13403 667
26 B 45 ENTQ 17256 91
8 S 46 QQNJ 4977 800
11 S 47 TQMN 5446 419
29 B 48 DPEJ 11631 693
17 S 49 IQAX 16763 788
27 S 50 ADUY 12603 62
1 S 51 JTHI 6125 164
1 B 52 VJHP 15074 587
27 B 53 RVGA 16207 704
16 B 54 DNZA 6826 155
21 B 55 OKRR 7990 305
1 B 56 FRVV 18986 196
3 B 57 JLDQ 7374 265
5 B 58 LCCQ 12938 208
7 B 59 FKVQ 14133 646
13 S 60 UVJG 6615 247
5 B 61 OIDC 18861 266
6 S 62 QGGV 5289 335
29 S 63 OMKM 16879 12
24 B 64 KPLA 18909 238
23 S 65 IBIF 1314 239
14 S 66 TUWP 6381 638
5 B 67 NUIN 1854 294
25 S 68 WMYL 13238 661
3 S 69 ZIIJ 9617 333
28 B 70 UKIR 14876 296
20 S 71 FHES 14444 306
20 S 72 OXSC 17693 32
13 B 73 IPPZ 18703 744
11 S 74 CYFZ 4307 852
6 S 75 LCCQ 15595 978
12 S 76 UGJO 15601 358
28 S 77 ENTQ 3307 464
7 B 78 RLGA 3317 869
18 B 79 ZPFY 575 186
21 S 80 PWSN 1531 927
8 S 81 JDKE 7090 560
12 B 82 RXNL 15363 600
12 B 83 CLVT 5055 825
16 B 84 SKFK 19123 231
25 S 85 DNDP 3728 113
8 B 86 SKZO 6756 391
1 B 87 ZUBX 18573 607
24 S 88 HQUS 8467 510
3 B 89 KQAO 11290 665
8 B 90 UKIR 18823 140
22 S 91 NPFL 15654 909
21 B 92 NJRN 17233 722
12 B 93 PKNA 314 736
25 B 94 MRKC 17746 59
8 B 95 GCEB 354 866
9 S 96 JFXE 9422 35
29 B 97 BCZS 1670 244
20 B 98 NBXI 6451 896
22 B 99 ZVIO 1371 994
20 S 100 QTZY 19286 88
19 S 101 RLGA 15166 67
0 S 102 PHFJ 14383 180
24 B 103 GXUG 18341 245
29 S 104 YRPP 5981 473
9 B 105 LRDR 9138 717
28 S 106 TFYF 1685 347
13 S 107 DDGV 14511 390
29 B 108 DNDP 5239 143
14 B 109 TYHV 10132 249
0 B 110 MRKC 13355 870
24 S 111 EIRS 4832 727
25 B 112 ZWNY 10880 237
22 B 113 LRDR 419 812
22 B 114 DAWR 13318 440
11 B 115 VTNB 9962 864
23 B 116 GPCI 17576 467
15 B 117 GRCW 15027 132
7 B 118 ZWLU 13188 528
21 B 119 LDUM 9077 881
12 B 120 KSEP 7723 131
14 S 121 CYER 8260 302
6 S 122 EAAF 2661 348
26 B 123 RXNL 5603 770
28 S 124 CWMH 13467 909
6 S 125 RXNL 8860 655
6 B 126 KSNN 19234 243
27 S 127 QRWL 9703 803
12 S 128 RXNF 18438 580
24 S 129 DZAG 12713 97
12 S 130 JRYS 3581 685
19 B 131 RZGX 17334 156
17 B 132 EXRB 16866 792
19 S 133 URMC 12070 422
13 S 134 CYFZ 17414 598
0 B 135 ZEAU 7011 355
1 S 136 XDOO 3074 182
17 B 137 LUAP 8203 472
6 S 138 ZUBX 14735 935
19 B 139 ZJSC 11148 777
11 S 140 KWCQ 4653 338
6 B 141 UOLR 12692 428
4 B 142 EZVK 6298 710
13 B 143 LRDR 5443 626
14 S 144 YCLF 5566 759
29 S 145 SWVO 8533 816
19 B 146 KPLA 1925 501
14 S 147 RUOF 752 817
2 S 148 DPXG 4907 339
13 S 149 WQNP 6260 634
7 S 150 NLVH 15028 589
9 S 151 QQNJ 15858 778
22 B 152 LQPZ 9489 331
21 S 153 NXBM 13182 753
21 S 154 NPFL 3641 366
5 S 155 RICY 12932 33
9 B 156 GCEB 11495 550
5 B 157 ENTQ 432 168
11 B 158 CFSQ 10146 855
20 S 159 NUIN 15776 877
2 B 160 FAMN 8094 55
1 B 161 PMCI 3302 104
29 S 162 RLYZ 19473 284
3 S 163 HGRP 7900 580
20 B 164 OBEV 17718 407
18 B 165 IPVB 12184 547
2 B 166 KWID 6498 527
25 S 167 VCXR 13342 880
12 S 168 REAH 5716 34
4 B 169 SOSM 7432 612
1 S 170 CWMH 483 434
25 S 171 ENTQ 15663 384
21 B 172 SRAV 7717 596
24 B 173 IQAX 13616 811
25 S 174 CYFZ 3514 711
14 B 175 KWCQ 18266 723
6 S 176 XAJS 11291 62
27 B 177 TKFX 10464 367
29 B 178 QMZS 14320 726
13 B 179 FAPG 9933 731
20 S 180 GCSQ 15290 885
22 B 181 NPWO 9046 454
6 S 182 SUDL 6678 332
7 B 183 TDTV 14629 116
4 S 184 AAPR 3176 312
1 S 185 UNDP 15896 312
15 B 186 BEVM 258 524
21 B 187 RICY 7796 798
19 S 188 HVSF 12770 401
8 S 189 FKNR 14516 331
16 B 190 LRDR 5955 293
23 S 191 PWMS 8397 212
8 B 192 LMOP 4740 43
5 S 193 PQXX 14643 644
28 S 194 UBUU 184 24
26 S 195 GEVQ 18056 136
14 B 196 CMDC 5459 109
12 B 197 RXNL 8870 495
0 S 198 ZRIH 9253 417
5 S 199 UJKL 10482 657
26 S 200 SWVO 14657 761
28 S 201 IACA 2349 419
8 B 202 UOLR 13110 615
11 B 203 ZRIH 13892 130
8 B 204 YQBN 14322 691
20 S 205 PHPF 1234 543
4 S 206 WOTX 5265 491
9 B 207 FCYA 3711 268
12 B 208 XVSU 7074 294
6 B 209 OAOV 16836 849
6 B 210 GVVX 15584 39
24 S 211 XDOO 15245 362
7 B 212 QVZF 7478 724
2 S 213 JTHI 17957 343
12 B 214 RXMD 3465 299
16 B 215 GWDO 12011 823
15 B 216 ZHSN 4367 759
0 B 217 LQPZ 18103 152
25 S 218 DUSF 11506 512
16 S 219 ZVIO 4591 203
23 B 220 CSNF 457 741
22 S 221 QTZY 731 476
14 S 222 ZWLU 2511 534
16 B 223 CHZU 18350 141
20 S 224 UJKL 6614 644
27 B 225 DUBW 15787 400
27 B 226 OZAF 6906 631
23 B 227 WISB 10636 857
7 S 228 OXSC 7998 719
17 S 229 PWMS 2286 62
26 S 230 SKFK 18530 386
5 B 231 OSUM 5005 640
10 S 232 LUAP 13848 425
3 S 233 HNEV 18592 546
24 B 234 BIPE 17312 630
2 S 235 JNCW 13134 416
26 B 236 LRDR 1447 270
2 B 237 OPIS 14011 796
29 S 238 BZJB 956 686
3 B 239 QQNJ 10158 781
2 S 240 VJHP 2882 584
0 B 241 NDJW 19907 458
4 S 242 URMC 5017 447
14 S 243 BCZS 3208 633
10 S 244 ADHP 4410 444
24 S 245 HLNB 5649 43
13 B 246 PWMS 16052 725
2 S 247 ZJSC 486 299
25 B 248 KSFL 628 14
25 S 249 SOSM 17445 460
14 S 250 ONZY 12016 111
28 B 251 HYLH 8430 999
9 S 252 NJRN 10306 121
4 B 253 FCYA 2312 877
1 S 254 ZBCH 4455 562
4 S 255 NHCH 8913 695
21 S 256 FHES 18907 692
11 S 257 GWDO 17731 762
1 S 258 HLNB 1367 243
16 S 259 KKCN 17022 690
15 B 260 YUUR 8567 30
18 B 261 LQPZ 16471 706
27 B 262 MVOJ 7936 129
2 S 263 MPCM 13362 145
4 B 264 PMCI 15088 54
4 B 265 WEAX 9943 386
28 S 266 BCZS 9051 398
4 B 267 XKQE 12279 24
29 B 268 KLRO 10357 154
16 B 269 ZPFY 645 844
7 B 270 EAAF 18892 717
23 B 271 RLYZ 8742 772
23 B 272 LOAJ 11965 910
11 S 273 DMRH 381 487
14 S 274 OPIS 10263 984
18 B 275 NPWO 8347 206
10 B 276 TASJ 5927 430
12 B 277 KNIG 12487 492
18 S 278 HNEV 6306 510
10 S 279 SAJU 2819 388
5 B 280 XAGL 9060 552
15 B 281 WHAG 809 230
15 S 282 IULN 14045 965
21 B 283 SFPA 14568 366
23 B 284 WQMV 10725 606
11 S 285 NHCH 11107 212
18 S 286 NBCZ 17203 36
0 S 287 LMOP 16820 224
25 S 288 PBMA 4016 853
16 B 289 ZWNY 2721 867
10 B 290 JRYS 97 386
8 S 291 RXMD 19967 735
3 B 292 ELZD 17230 645
12 B 293 BOXK 7721 485
15 B 294 DBAJ 13521 46
24 S 295 ZATA 13288 262
26 B 296 XEEH 7566 996
3 S 297 LYUU 8941 978
14 B 298 XZST 5633 589
9 B 299 TUWP 827 137
12 B 300 TDAT 11849 397
24 B 301 VSCR 3343 256
18 B 302 TDTV 14006 162
14 B 303 ASJA 13453 709
4 S 304 JLDQ 4547 478
17 S 305 FJPN 2644 645
12 S 306 CHZU 9062 233
3 S 307 ADUY 5969 262
18 S 308 QVMV 5600 354
3 S 309 LCCQ 12420 787
2 S 310 ZZDA 8216 477
24 B 311 XEEH 4646 490
20 S 312 UVJG 12253 99
19 S 313 IULN 11359 488
13 S 314 NJRN 3105 213
19 S 315 ZJSC 11311 436
21 S 316 EZVK 2708 187
18 B 317 IULN 12543 949
29 B 318 QVMC 9718 188
25 S 319 FJPN 14186 916
4 S 320 DAWR 8109 174
19 B 321 QRXI 5352 391
28 S 322 OKRR 11662 201
13 S 323 HQLW 11284 340
5 S 324 YHZV 12242 157
18 B 325 YABY 2019 315
8 S 326 JNCW 4497 945
26 B 327 BOXK 703 131
1 S 328 JDKE 16821 645
6 B 329 QFAK 5111 537
13 S 330 BZEJ 7214 730
21 B 331 CMDC 352 425
4 S 332 SSCV 19633 575
13 S 333 UGJO 13225 484
1 B 334 KQTY 2342 312
2 S 335 XVSU 10728 521
28 S 336 OAOV 6775 561
24 S 337 DPEJ 16190 133
20 B 338 ZVIO 14918 476
16 B 339 DRSD 5871 499
18 B 340 PMCI 18935 500
11 B 341 EXRB 6996 919
9 S 342 XQQB 2097 182
26 S 343 PQXX 2325 611
22 B 344 NJRN 720 794
25 S 345 ZHSN 15406 21
24 B 346 ASGE 19871 77
18 S 347 VCXR 1120 413
9 S 348 NPFL 2722 513
22 S 349 IBIF 3304 617
20 B 350 PSZR 7821 168
11 S 351 ZWLU 3368 109
2 S 352 ADUY 376 889
19 S 353 VNCS 5746 778
